2024-11-13 02:18:05,222 - app.modules.dataset.routes - ERROR - Error al agregar la calificaci√≥n
Traceback (most recent call last):
  File "/home/david/Escritorio/berenjena-hub/venv/lib/python3.12/site-packages/sqlalchemy/engine/base.py", line 1967, in _exec_single_context
    self.dialect.do_execute(
  File "/home/david/Escritorio/berenjena-hub/venv/lib/python3.12/site-packages/sqlalchemy/engine/default.py", line 924, in do_execute
    cursor.execute(statement, parameters)
  File "/home/david/Escritorio/berenjena-hub/venv/lib/python3.12/site-packages/pymysql/cursors.py", line 153, in execute
    result = self._query(query)
             ^^^^^^^^^^^^^^^^^^
  File "/home/david/Escritorio/berenjena-hub/venv/lib/python3.12/site-packages/pymysql/cursors.py", line 322, in _query
    conn.query(q)
  File "/home/david/Escritorio/berenjena-hub/venv/lib/python3.12/site-packages/pymysql/connections.py", line 563, in query
    self._affected_rows = self._read_query_result(unbuffered=unbuffered)
                          ^^^^^^^^^^^^^^^^^^^^^^^^^^^^^^^^^^^^^^^^^^^^^^
  File "/home/david/Escritorio/berenjena-hub/venv/lib/python3.12/site-packages/pymysql/connections.py", line 825, in _read_query_result
    result.read()
  File "/home/david/Escritorio/berenjena-hub/venv/lib/python3.12/site-packages/pymysql/connections.py", line 1199, in read
    first_packet = self.connection._read_packet()
                   ^^^^^^^^^^^^^^^^^^^^^^^^^^^^^^
  File "/home/david/Escritorio/berenjena-hub/venv/lib/python3.12/site-packages/pymysql/connections.py", line 775, in _read_packet
    packet.raise_for_error()
  File "/home/david/Escritorio/berenjena-hub/venv/lib/python3.12/site-packages/pymysql/protocol.py", line 219, in raise_for_error
    err.raise_mysql_exception(self._data)
  File "/home/david/Escritorio/berenjena-hub/venv/lib/python3.12/site-packages/pymysql/err.py", line 150, in raise_mysql_exception
    raise errorclass(errno, errval)
pymysql.err.IntegrityError: (1452, 'Cannot add or update a child row: a foreign key constraint fails (`uvlhubdb`.`ratings`, CONSTRAINT `ratings_ibfk_2` FOREIGN KEY (`user_id`) REFERENCES `user` (`id`) ON DELETE CASCADE)')

The above exception was the direct cause of the following exception:

Traceback (most recent call last):
  File "/home/david/Escritorio/berenjena-hub/app/modules/dataset/routes.py", line 359, in rate
    rating = rating_service.add_rating(user_id, dataset_id, quality, size, usability)
             ^^^^^^^^^^^^^^^^^^^^^^^^^^^^^^^^^^^^^^^^^^^^^^^^^^^^^^^^^^^^^^^^^^^^^^^^
  File "/home/david/Escritorio/berenjena-hub/app/modules/dataset/services.py", line 236, in add_rating
    return self.repository.add_rating(dataset_id=dataset_id, user_id=user_id, quality=quality, size=size, usability=usability)
           ^^^^^^^^^^^^^^^^^^^^^^^^^^^^^^^^^^^^^^^^^^^^^^^^^^^^^^^^^^^^^^^^^^^^^^^^^^^^^^^^^^^^^^^^^^^^^^^^^^^^^^^^^^^^^^^^^^^
  File "/home/david/Escritorio/berenjena-hub/app/modules/dataset/repositories.py", line 158, in add_rating
    self.db_session.commit()
  File "/home/david/Escritorio/berenjena-hub/venv/lib/python3.12/site-packages/sqlalchemy/orm/scoping.py", line 597, in commit
    return self._proxied.commit()
           ^^^^^^^^^^^^^^^^^^^^^^
  File "/home/david/Escritorio/berenjena-hub/venv/lib/python3.12/site-packages/sqlalchemy/orm/session.py", line 2017, in commit
    trans.commit(_to_root=True)
  File "<string>", line 2, in commit
  File "/home/david/Escritorio/berenjena-hub/venv/lib/python3.12/site-packages/sqlalchemy/orm/state_changes.py", line 139, in _go
    ret_value = fn(self, *arg, **kw)
                ^^^^^^^^^^^^^^^^^^^^
  File "/home/david/Escritorio/berenjena-hub/venv/lib/python3.12/site-packages/sqlalchemy/orm/session.py", line 1302, in commit
    self._prepare_impl()
  File "<string>", line 2, in _prepare_impl
  File "/home/david/Escritorio/berenjena-hub/venv/lib/python3.12/site-packages/sqlalchemy/orm/state_changes.py", line 139, in _go
    ret_value = fn(self, *arg, **kw)
                ^^^^^^^^^^^^^^^^^^^^
  File "/home/david/Escritorio/berenjena-hub/venv/lib/python3.12/site-packages/sqlalchemy/orm/session.py", line 1277, in _prepare_impl
    self.session.flush()
  File "/home/david/Escritorio/berenjena-hub/venv/lib/python3.12/site-packages/sqlalchemy/orm/session.py", line 4341, in flush
    self._flush(objects)
  File "/home/david/Escritorio/berenjena-hub/venv/lib/python3.12/site-packages/sqlalchemy/orm/session.py", line 4476, in _flush
    with util.safe_reraise():
         ^^^^^^^^^^^^^^^^^^^
  File "/home/david/Escritorio/berenjena-hub/venv/lib/python3.12/site-packages/sqlalchemy/util/langhelpers.py", line 146, in __exit__
    raise exc_value.with_traceback(exc_tb)
  File "/home/david/Escritorio/berenjena-hub/venv/lib/python3.12/site-packages/sqlalchemy/orm/session.py", line 4437, in _flush
    flush_context.execute()
  File "/home/david/Escritorio/berenjena-hub/venv/lib/python3.12/site-packages/sqlalchemy/orm/unitofwork.py", line 466, in execute
    rec.execute(self)
  File "/home/david/Escritorio/berenjena-hub/venv/lib/python3.12/site-packages/sqlalchemy/orm/unitofwork.py", line 642, in execute
    util.preloaded.orm_persistence.save_obj(
  File "/home/david/Escritorio/berenjena-hub/venv/lib/python3.12/site-packages/sqlalchemy/orm/persistence.py", line 93, in save_obj
    _emit_insert_statements(
  File "/home/david/Escritorio/berenjena-hub/venv/lib/python3.12/site-packages/sqlalchemy/orm/persistence.py", line 1233, in _emit_insert_statements
    result = connection.execute(
             ^^^^^^^^^^^^^^^^^^^
  File "/home/david/Escritorio/berenjena-hub/venv/lib/python3.12/site-packages/sqlalchemy/engine/base.py", line 1418, in execute
    return meth(
           ^^^^^
  File "/home/david/Escritorio/berenjena-hub/venv/lib/python3.12/site-packages/sqlalchemy/sql/elements.py", line 515, in _execute_on_connection
    return connection._execute_clauseelement(
           ^^^^^^^^^^^^^^^^^^^^^^^^^^^^^^^^^^
  File "/home/david/Escritorio/berenjena-hub/venv/lib/python3.12/site-packages/sqlalchemy/engine/base.py", line 1640, in _execute_clauseelement
    ret = self._execute_context(
          ^^^^^^^^^^^^^^^^^^^^^^
  File "/home/david/Escritorio/berenjena-hub/venv/lib/python3.12/site-packages/sqlalchemy/engine/base.py", line 1846, in _execute_context
    return self._exec_single_context(
           ^^^^^^^^^^^^^^^^^^^^^^^^^^
  File "/home/david/Escritorio/berenjena-hub/venv/lib/python3.12/site-packages/sqlalchemy/engine/base.py", line 1986, in _exec_single_context
    self._handle_dbapi_exception(
  File "/home/david/Escritorio/berenjena-hub/venv/lib/python3.12/site-packages/sqlalchemy/engine/base.py", line 2353, in _handle_dbapi_exception
    raise sqlalchemy_exception.with_traceback(exc_info[2]) from e
  File "/home/david/Escritorio/berenjena-hub/venv/lib/python3.12/site-packages/sqlalchemy/engine/base.py", line 1967, in _exec_single_context
    self.dialect.do_execute(
  File "/home/david/Escritorio/berenjena-hub/venv/lib/python3.12/site-packages/sqlalchemy/engine/default.py", line 924, in do_execute
    cursor.execute(statement, parameters)
  File "/home/david/Escritorio/berenjena-hub/venv/lib/python3.12/site-packages/pymysql/cursors.py", line 153, in execute
    result = self._query(query)
             ^^^^^^^^^^^^^^^^^^
  File "/home/david/Escritorio/berenjena-hub/venv/lib/python3.12/site-packages/pymysql/cursors.py", line 322, in _query
    conn.query(q)
  File "/home/david/Escritorio/berenjena-hub/venv/lib/python3.12/site-packages/pymysql/connections.py", line 563, in query
    self._affected_rows = self._read_query_result(unbuffered=unbuffered)
                          ^^^^^^^^^^^^^^^^^^^^^^^^^^^^^^^^^^^^^^^^^^^^^^
  File "/home/david/Escritorio/berenjena-hub/venv/lib/python3.12/site-packages/pymysql/connections.py", line 825, in _read_query_result
    result.read()
  File "/home/david/Escritorio/berenjena-hub/venv/lib/python3.12/site-packages/pymysql/connections.py", line 1199, in read
    first_packet = self.connection._read_packet()
                   ^^^^^^^^^^^^^^^^^^^^^^^^^^^^^^
  File "/home/david/Escritorio/berenjena-hub/venv/lib/python3.12/site-packages/pymysql/connections.py", line 775, in _read_packet
    packet.raise_for_error()
  File "/home/david/Escritorio/berenjena-hub/venv/lib/python3.12/site-packages/pymysql/protocol.py", line 219, in raise_for_error
    err.raise_mysql_exception(self._data)
  File "/home/david/Escritorio/berenjena-hub/venv/lib/python3.12/site-packages/pymysql/err.py", line 150, in raise_mysql_exception
    raise errorclass(errno, errval)
sqlalchemy.exc.IntegrityError: (pymysql.err.IntegrityError) (1452, 'Cannot add or update a child row: a foreign key constraint fails (`uvlhubdb`.`ratings`, CONSTRAINT `ratings_ibfk_2` FOREIGN KEY (`user_id`) REFERENCES `user` (`id`) ON DELETE CASCADE)')
[SQL: INSERT INTO ratings (user_id, dataset_id, quality, size, usability, total_rating, created_at) VALUES (%(user_id)s, %(dataset_id)s, %(quality)s, %(size)s, %(usability)s, %(total_rating)s, %(created_at)s)]
[parameters: {'user_id': '4', 'dataset_id': '1', 'quality': 3.0, 'size': 3.0, 'usability': 1.0, 'total_rating': 2.3333333333333335, 'created_at': datetime.datetime(2024, 11, 13, 1, 18, 5, 218681, tzinfo=datetime.timezone.utc)}]
(Background on this error at: https://sqlalche.me/e/20/gkpj)
